<?xml version="1.0" encoding="utf-8"?>
<robot name="RM75B_with_Gripper">

  <link name="base_link">
    <inertial>
      <origin xyz="0.00049987 5.2709E-05 0.060019" rpy="0 0 0" />
      <mass value="1.862" />
      <inertia ixx="0.0017232" ixy="-3.1058E-06" ixz="-3.7924E-05" iyy="0.0017051" iyz="1.3691E-06" izz="0.00090158" />
    </inertial>
    <visual>
      <geometry><mesh filename="package://RM75-B/meshes/base_link.STL" /></geometry>
      <material name=""><color rgba="1 1 1 1" /></material>
    </visual>
    <collision>
      <geometry><mesh filename="package://RM75-B/meshes/base_link.STL" /></geometry>
    </collision>
  </link>

  <link name="link_1">
    <visual><geometry><mesh filename="package://RM75-B/meshes/link_1.STL" /></geometry></visual>
  </link>
  <joint name="joint_1" type="revolute">
    <origin xyz="0 0 0.2405" rpy="0 0 0" />
    <parent link="base_link" /><child link="link_1" />
    <axis xyz="0 0 1" />
    <limit lower="-3.106" upper="3.106" effort="60" velocity="3.14" />
  </joint>

  <link name="link_2">
    <visual><geometry><mesh filename="package://RM75-B/meshes/link_2.STL" /></geometry></visual>
  </link>
  <joint name="joint_2" type="revolute">
    <origin xyz="0 0 0" rpy="-1.5708 0 0" />
    <parent link="link_1" /><child link="link_2" />
    <axis xyz="0 0 1" />
    <limit lower="-2.2689" upper="2.2689" effort="60" velocity="3.14" />
  </joint>

  <link name="link_3">
    <visual><geometry><mesh filename="package://RM75-B/meshes/link_3.STL" /></geometry></visual>
  </link>
  <joint name="joint_3" type="revolute">
    <origin xyz="0 -0.256 0" rpy="1.5708 0 0" />
    <parent link="link_2" /><child link="link_3" />
    <axis xyz="0 0 1" />
    <limit lower="-3.106" upper="3.106" effort="30" velocity="3.14" />
  </joint>

  <link name="link_4">
    <visual><geometry><mesh filename="package://RM75-B/meshes/link_4.STL" /></geometry></visual>
  </link>
  <joint name="joint_4" type="revolute">
    <origin xyz="0 0 0" rpy="-1.5708 0 0" />
    <parent link="link_3" /><child link="link_4" />
    <axis xyz="0 0 1" />
    <limit lower="-2.356" upper="2.356" effort="30" velocity="3.14" />
  </joint>

  <link name="link_5">
    <visual><geometry><mesh filename="package://RM75-B/meshes/link_5.STL" /></geometry></visual>
  </link>
  <joint name="joint_5" type="revolute">
    <origin xyz="0 -0.21 0" rpy="1.5708 0 0" />
    <parent link="link_4" /><child link="link_5" />
    <axis xyz="0 0 1" />
    <limit lower="-3.106" upper="3.106" effort="10" velocity="3.14" />
  </joint>

  <link name="link_6">
    <visual><geometry><mesh filename="package://RM75-B/meshes/link_6.STL" /></geometry></visual>
  </link>
  <joint name="joint_6" type="revolute">
    <origin xyz="0 0 0" rpy="-1.5708 0 0" />
    <parent link="link_5" /><child link="link_6" />
    <axis xyz="0 0 1" />
    <limit lower="-2.234" upper="2.234" effort="10" velocity="3.14" />
  </joint>

  <link name="link_7">
    <inertial>
      <origin xyz="0.001094 -0.000077 -0.010119" rpy="0 0 0" />
      <mass value="0.107" />
      <inertia ixx="0.000044123" ixy="-0.000000064" ixz="0.0000003" iyy="0.000035078" iyz="-0.000000029" izz="0.000065445" />
    </inertial>
    <visual>
      <geometry><mesh filename="package://RM75-B/meshes/link_7.STL" /></geometry>
    </visual>
    <collision>
      <geometry><mesh filename="package://RM75-B/meshes/link_7.STL" /></geometry>
    </collision>
  </link>
  <joint name="joint_7" type="revolute">
    <origin xyz="0 -0.144 0" rpy="1.5708 0 0" />
    <parent link="link_6" /><child link="link_7" />
    <axis xyz="0 0 1" />
    <limit lower="-6.28" upper="6.28" effort="10" velocity="3.14" />
  </joint>

  <joint name="arm_gripper_joint" type="fixed">
    <origin xyz="0 0 0" rpy="0 0 0" />
    <parent link="link_7" />
    <child link="gripper_base" />
  </joint>

  <link name="gripper_base" />

  <link name="gripper_base_link">
    <visual>
      <geometry><mesh filename="package://crt_ctag2f90d_gripper_visualization/meshes/base_link.STL" /></geometry>
      <material name=""><color rgba="0.615686274509804 0.63921568627451 0.674509803921569 1" /></material>
    </visual>
    <collision>
      <geometry><mesh filename="package://crt_ctag2f90d_gripper_visualization/meshes/base_link.STL" /></geometry>
    </collision>
  </link>

  <joint name="gripper_base_link_Joint" type="fixed">
    <origin xyz="0 0 0" rpy="0 0 0" />
    <parent link="gripper_base" />
    <child link="gripper_base_link" />
  </joint>

  <link name="gripper_Left_1_Link">
    <visual><geometry><mesh filename="package://crt_ctag2f90d_gripper_visualization/meshes/Left_1_Link.STL" /></geometry></visual>
  </link>
  <joint name="gripper_Left_1_Joint" type="revolute">
    <origin xyz="0.030141 0 0.10415" rpy="1.5708 0 0" />
    <parent link="gripper_base_link" /><child link="gripper_Left_1_Link" />
    <axis xyz="0 0 -1" />
    <limit lower="-0.91" upper="0" effort="10" velocity="10" />
  </joint>

  <link name="gripper_Left_Support_Link">
    <visual><geometry><mesh filename="package://crt_ctag2f90d_gripper_visualization/meshes/Left_Support_Link.STL" /></geometry></visual>
  </link>
  <joint name="gripper_Left_Support_Joint" type="revolute">
    <origin xyz="0.040359 0.037365 0" rpy="0 0 0" />
    <parent link="gripper_Left_1_Link" /><child link="gripper_Left_Support_Link" />
    <axis xyz="0 0 -1" />
    <limit lower="-3.14" upper="3.14" effort="10" velocity="10" />
    <mimic joint="gripper_Left_1_Joint" multiplier="-1" offset="0" />
  </joint>

  <link name="gripper_Left_2_Link">
    <visual><geometry><mesh filename="package://crt_ctag2f90d_gripper_visualization/meshes/Left_2_Link.STL" /></geometry></visual>
  </link>
  <joint name="gripper_Left_2_Joint" type="revolute">
    <origin xyz="0.016 0 0.121" rpy="1.5708 0 0" />
    <parent link="gripper_base_link" /><child link="gripper_Left_2_Link" />
    <axis xyz="0 0 -1" />
    <limit lower="-3.14" upper="3.14" effort="10" velocity="10" />
    <mimic joint="gripper_Left_1_Joint" multiplier="1" offset="0" />
  </joint>

  <link name="gripper_Right_1_Link">
    <visual><geometry><mesh filename="package://crt_ctag2f90d_gripper_visualization/meshes/Right_1_Link.STL" /></geometry></visual>
  </link>
  <joint name="gripper_Right_1_Joint" type="revolute">
    <origin xyz="-0.030141 0 0.10415" rpy="1.5708 0 3.1416" />
    <parent link="gripper_base_link" /><child link="gripper_Right_1_Link" />
    <axis xyz="0 0 1" />
    <limit lower="-3.14" upper="3.14" effort="10" velocity="10" />
    <mimic joint="gripper_Left_1_Joint" multiplier="-1" offset="0" />
  </joint>

  <link name="gripper_Right_Support_Link">
    <visual><geometry><mesh filename="package://crt_ctag2f90d_gripper_visualization/meshes/Right_Support_Link.STL" /></geometry></visual>
  </link>
  <joint name="gripper_Right_Support_Joint" type="revolute">
    <origin xyz="0.040359 0.037365 0" rpy="0 0 0" />
    <parent link="gripper_Right_1_Link" /><child link="gripper_Right_Support_Link" />
    <axis xyz="0 0 -1" />
    <limit lower="-3.14" upper="3.14" effort="10" velocity="10" />
    <mimic joint="gripper_Left_1_Joint" multiplier="-1" offset="0" />
  </joint>

  <link name="gripper_Right_2_Link">
    <visual><geometry><mesh filename="package://crt_ctag2f90d_gripper_visualization/meshes/Right_2_Link.STL" /></geometry></visual>
  </link>
  <joint name="gripper_Right_2_Joint" type="revolute">
    <origin xyz="-0.016 0 0.121" rpy="1.5708 0 3.1416" />
    <parent link="gripper_base_link" /><child link="gripper_Right_2_Link" />
    <axis xyz="0 0 1" />
    <limit lower="-3.14" upper="3.14" effort="10" velocity="10" />
    <mimic joint="gripper_Left_1_Joint" multiplier="-1" offset="0" />
  </joint>

</robot>