<?xml version="1.0" ?>
<!-- RM75-B with ChangingTek AG2F90-C Gripper -->
<robot name="RM75_AG2F90C">
  <!-- ================= ARM LINKS ================= -->
  <link name="base_link">
    <inertial>
      <origin xyz="0.00049987 5.2709E-05 0.060019" rpy="0 0 0"/>
      <mass value="1.862"/>
      <inertia ixx="0.0017232" ixy="-3.1058E-06" ixz="-3.7924E-05" iyy="0.0017051" iyz="1.3691E-06" izz="0.00090158"/>
    </inertial>
    <visual>
      <geometry><mesh filename="meshes/base_link.STL"/></geometry>
      <material name="arm_white"><color rgba="1 1 1 1"/></material>
    </visual>
    <collision>
      <geometry><mesh filename="meshes/base_link.STL"/></geometry>
    </collision>
  </link>

  <link name="link_1">
    <inertial>
      <origin rpy="0 0 0" xyz="-0.002 0.02692 -0.01332"/>
      <mass value="2.16"/>
      <inertia ixx="0.00539427" ixy="1.095E-05" ixz="1.635E-06" iyy="0.0048979" iyz="0.000793" izz="0.00311573"/>
    </inertial>
    <visual><geometry><mesh filename="meshes/link_1.STL"/></geometry><material name="arm_white"/></visual>
    <collision><geometry><mesh filename="meshes/link_1.STL"/></geometry></collision>
  </link>
  <joint name="joint_1" type="revolute">
    <origin xyz="0 0 0.2405" rpy="0 0 0"/><!-- 逆时针旋转90度 -->
    <parent link="base_link"/><child link="link_1"/>
    <axis xyz="0 0 1"/>
    <limit lower="-3.106" upper="3.106" effort="60" velocity="3.14"/>
  </joint>

  <link name="link_2">
    <inertial>
      <origin rpy="0 0 0" xyz="0.03531 -0.21398 0.03386"/>
      <mass value="1.71"/>
      <inertia ixx="0.0248674" ixy="-0.00430651" ixz="-0.00067797" iyy="0.00485548" iyz="0.00457245" izz="0.02387827"/>
    </inertial>
    <visual><geometry><mesh filename="meshes/link_2.STL"/></geometry><material name="arm_white"/></visual>
    <collision><geometry><mesh filename="meshes/link_2.STL"/></geometry></collision>
  </link>
  <joint name="joint_2" type="revolute">
    <origin xyz="0 0 0" rpy="-1.5708 0 0"/>
    <parent link="link_1"/><child link="link_2"/>
    <axis xyz="0 0 1"/>
    <limit lower="-2.2689" upper="2.2689" effort="60" velocity="3.14"/>
  </joint>

  <link name="link_3">
    <inertial>
      <origin rpy="0 0 0" xyz="0.06781 0.10749 0.01457"/>
      <mass value="1.384"/>
      <inertia ixx="0.0053694" ixy="0.0014185" ixz="-0.00092094" iyy="0.0032423" iyz="-0.00169178" izz="0.00501731"/>
    </inertial>
    <visual><geometry><mesh filename="meshes/link_3.STL"/></geometry><material name="arm_white"/></visual>
    <collision><geometry><mesh filename="meshes/link_3.STL"/></geometry></collision>
  </link>
  <joint name="joint_3" type="revolute">
    <origin xyz="0 -0.256 0" rpy="1.5708 0 0"/>
    <parent link="link_2"/><child link="link_3"/>
    <axis xyz="0 0 1"/>
    <limit lower="-3.106" upper="3.106" effort="30" velocity="3.14"/>
  </joint>

  <link name="link_4">
    <inertial>
      <origin rpy="0 0 0" xyz="-0.00021 0.02578 -0.02538"/>
      <mass value="1.115"/>
      <inertia ixx="0.00439263" ixy="5.028E-05" ixz="1.374E-05" iyy="0.0040077" iyz="0.00045338" izz="0.00110321"/>
    </inertial>
    <visual><geometry><mesh filename="meshes/link_4.STL"/></geometry><material name="arm_white"/></visual>
    <collision><geometry><mesh filename="meshes/link_4.STL"/></geometry></collision>
  </link>
  <joint name="joint_4" type="revolute">
    <origin xyz="0 0 0" rpy="-1.5708 0 0"/>
    <parent link="link_3"/><child link="link_4"/>
    <axis xyz="0 0 1"/>
    <limit lower="-2.356" upper="2.356" effort="30" velocity="3.14"/>
  </joint>

  <link name="link_5">
    <inertial>
      <origin rpy="0 0 0" xyz="0.05428 0.01781 0.00543"/>
      <mass value="1.275"/>
      <inertia ixx="0.001202758" ixy="0.000492428" ixz="-0.00039147" iyy="0.0022876" iyz="-1.235E-04" izz="0.0026866"/>
    </inertial>
    <visual><geometry><mesh filename="meshes/link_5.STL"/></geometry><material name="arm_white"/></visual>
    <collision><geometry><mesh filename="meshes/link_5.STL"/></geometry></collision>
  </link>
  <joint name="joint_5" type="revolute">
    <origin xyz="0 -0.21 0" rpy="1.5708 0 0"/>
    <parent link="link_4"/><child link="link_5"/>
    <axis xyz="0 0 1"/>
    <limit lower="-3.106" upper="3.106" effort="10" velocity="3.14"/>
  </joint>

  <link name="link_6">
    <inertial>
      <origin rpy="0 0 0" xyz="0 0.00064 -0.00952"/>
      <mass value="0.1096"/>
      <inertia ixx="4.5293E-05" ixy="0" ixz="0" iyy="4.8111E-05" iyz="0" izz="7.9715E-05"/>
    </inertial>
    <visual><geometry><mesh filename="meshes/link_6.STL"/></geometry><material name="arm_white"/></visual>
    <collision><geometry><mesh filename="meshes/link_6.STL"/></geometry></collision>
  </link>
  <joint name="joint_6" type="revolute">
    <origin xyz="0 0 0" rpy="-1.5708 0 0"/>
    <parent link="link_5"/><child link="link_6"/>
    <axis xyz="0 0 1"/>
    <limit lower="-2.234" upper="2.234" effort="10" velocity="3.14"/>
  </joint>

  <link name="link_7">
    <inertial>
      <origin xyz="0.001094 -0.000077 -0.010119" rpy="0 0 0"/>
      <mass value="0.107"/>
      <inertia ixx="0.000044123" ixy="-0.000000064" ixz="0.0000003" iyy="0.000035078" iyz="-0.000000029" izz="0.000065445"/>
    </inertial>
    <visual>
      <geometry><mesh filename="meshes/link_7.STL"/></geometry>
      <material name="arm_gray"><color rgba="0.514 0.514 0.514 1"/></material>
    </visual>
    <collision><geometry><mesh filename="meshes/link_7.STL"/></geometry></collision>
  </link>
  <joint name="joint_7" type="revolute">
    <origin xyz="0 -0.144 0" rpy="1.5708 1.0395 0"/><!-- 逆时针旋转15度 (pitch) -->
    <parent link="link_6"/><child link="link_7"/>
    <axis xyz="0 0 1"/>
    <limit lower="-6.28" upper="6.28" effort="10" velocity="3.14"/>
  </joint>

  <!-- ================= GRIPPER FLANGE (fixed to link_7) ================= -->
  <joint name="gripper_fix" type="fixed">
    <parent link="link_7"/>
    <child link="flange"/>
    <origin rpy="0 0 0" xyz="0 0 0"/>
  </joint>
  <link name="flange">
    <inertial>
      <origin xyz="-0.000388 0.002345 0.0"/>
      <mass value="0.114"/>
      <inertia ixx="0.000040105" ixy="0.000000214" ixz="0.0" iyy="0.000085776" iyz="0.0" izz="0.000054044"/>
    </inertial>
    <visual>
      <geometry><mesh filename="meshes/gripper/flange.obj"/></geometry>
    </visual>
    <collision>
      <geometry><mesh filename="meshes/gripper/flange.obj"/></geometry>
    </collision>
  </link>

  <!-- ================= GRIPPER BASE ================= -->
  <joint name="flange_joint" type="fixed">
    <origin xyz="0 0 0.0195"/>
    <parent link="flange"/>
    <child link="gripper_base"/>
  </joint>
  <link name="gripper_base">
    <inertial>
      <origin xyz="3.45207417426861E-05 -0.000141443719270944 0.0415526970475172"/>
      <mass value="0.310447980489903"/>
      <inertia ixx="0.000404388005636034" ixy="-6.8589621466727E-08" ixz="5.84928727366459E-08"
               iyy="0.000296494720930083" iyz="-1.79342738400452E-07" izz="0.000212447969282029"/>
    </inertial>
    <visual>
      <geometry><mesh filename="meshes/gripper/gripper_base.obj"/></geometry>
    </visual>
    <collision>
      <geometry><mesh filename="meshes/gripper/gripper_base.obj"/></geometry>
    </collision>
  </link>

  <!-- ================= LEFT FINGER CHAIN ================= -->
  <link name="left_1_link">
    <inertial>
      <origin xyz="-1.28088127539536E-18 0.0252734640095115 -0.00214040614650292"/>
      <mass value="0.0129014357535444"/>
      <inertia ixx="3.35976482443235E-06" ixy="-3.3181849198807E-25" ixz="-3.35726667613063E-23"
               iyy="1.65185846940368E-07" iyz="2.63476012977044E-07" izz="3.25394125032869E-06"/>
    </inertial>
    <visual><geometry><mesh filename="meshes/gripper/link_1.obj"/></geometry></visual>
    <collision><geometry><mesh filename="meshes/gripper/link_1.obj"/></geometry></collision>
  </link>
  <joint name="gripper_joint" type="revolute">
    <origin rpy="2.5708 0 0" xyz="0 -0.030141 0.090147"/><!-- 默认张开: roll +1 -->
    <parent link="gripper_base"/>
    <child link="left_1_link"/>
    <axis xyz="1 0 0"/>
    <limit effort="1000" lower="0" upper="1" velocity="2.0"/>
  </joint>

  <link name="left_up_link">
    <inertial>
      <origin xyz="8.69802213948566E-11 0.0124078988097444 -0.0072525614743534"/>
      <mass value="0.014692561982481"/>
      <inertia ixx="2.35283034039115E-06" ixy="3.49796352982052E-14" ixz="-4.72158842036621E-15"
               iyy="5.8942945477579E-07" iyz="7.05860796345956E-07" izz="2.07228020361883E-06"/>
    </inertial>
    <visual><geometry><mesh filename="meshes/gripper/up_link.obj"/></geometry></visual>
    <collision><geometry><mesh filename="meshes/gripper/up_link.obj"/></geometry></collision>
  </link>
  <joint name="left_up_Joint" type="revolute">
    <origin xyz="0 0.054804 -0.0046413" rpy="-1 0 0"/><!-- 默认张开: roll -1 (axis=-X) -->
    <parent link="left_1_link"/>
    <child link="left_up_link"/>
    <axis xyz="-1 0 0"/>
    <limit effort="1000" lower="0" upper="1" velocity="2.0"/>
    <mimic joint="gripper_joint" multiplier="1" offset="0"/>
  </joint>

  <link name="left_Pad_link">
    <inertial>
      <origin xyz="-3.83777509579761E-08 0.00303135276101582 0.0028336970357949"/>
      <mass value="0.0183171479595721"/>
      <inertia ixx="2.35683098270332E-06" ixy="-4.7353365844279E-12" ixz="-9.31433971475514E-13"
               iyy="9.08136064346118E-07" iyz="-1.55873132053129E-08" izz="3.18448591439082E-06"/>
    </inertial>
    <visual><geometry><mesh filename="meshes/gripper/pad_link.obj"/></geometry></visual>
    <collision><geometry><mesh filename="meshes/gripper/pad_link.obj"/></geometry></collision>
  </link>
  <joint name="left_Pad_Joint" type="fixed">
    <origin xyz="0 0.04125 -0.02425"/>
    <parent link="left_up_link"/>
    <child link="left_Pad_link"/>
  </joint>

  <link name="left_2_link">
    <inertial>
      <origin xyz="5.08224485200288E-06 0.0327050710040551 -0.00276963392800038"/>
      <mass value="0.0188752657753052"/>
      <inertia ixx="3.4145090175335E-06" ixy="-3.3317063785682E-22" ixz="-8.3582474326843E-22"
               iyy="2.86837057727488E-07" iyz="2.64809197911117E-07" izz="3.39111483394506E-06"/>
    </inertial>
    <visual><geometry><mesh filename="meshes/gripper/link_2.obj"/></geometry></visual>
    <collision><geometry><mesh filename="meshes/gripper/link_2.obj"/></geometry></collision>
  </link>
  <joint name="left_2_Joint" type="revolute">
    <origin rpy="2.5708 0 0" xyz="0 -0.016 0.107"/><!-- 默认张开: roll +1 -->
    <parent link="gripper_base"/>
    <child link="left_2_link"/>
    <axis xyz="1 0 0"/>
    <limit effort="1000" lower="0" upper="1" velocity="2.0"/>
    <mimic joint="gripper_joint" multiplier="1" offset="0"/>
  </joint>

  <!-- ================= RIGHT FINGER CHAIN ================= -->
  <link name="right_2_link">
    <inertial>
      <origin xyz="1.94651792710713E-17 0.0327174794493866 -0.00277053098700989"/>
      <mass value="0.0188856364479881"/>
      <inertia ixx="3.41458781978465E-06" ixy="2.85152078238725E-22" ixz="9.8903086622122E-22"
               iyy="2.86883124998043E-07" iyz="2.64817198026894E-07" izz="3.39114800103702E-06"/>
    </inertial>
    <visual><geometry><mesh filename="meshes/gripper/link_2.obj"/></geometry></visual>
    <collision><geometry><mesh filename="meshes/gripper/link_2.obj"/></geometry></collision>
  </link>
  <joint name="right_2_Joint" type="revolute">
    <origin rpy="2.5708 0 3.1416" xyz="0 0.016 0.107"/><!-- 默认张开: roll +1 -->
    <parent link="gripper_base"/>
    <child link="right_2_link"/>
    <axis xyz="1 0 0"/>
    <limit effort="1000" lower="0" upper="1" velocity="2.0"/>
    <mimic joint="gripper_joint" multiplier="1" offset="0"/>
  </joint>

  <link name="right_1_link">
    <inertial>
      <origin xyz="-5.25233292439781E-19 0.0252734640095115 -0.00214040614650291"/>
      <mass value="0.0129014357535444"/>
      <inertia ixx="3.35976482443235E-06" ixy="-3.94978742494071E-23" ixz="-2.72484926002331E-23"
               iyy="1.65185846940368E-07" iyz="2.63476012977044E-07" izz="3.25394125032869E-06"/>
    </inertial>
    <visual><geometry><mesh filename="meshes/gripper/link_1.obj"/></geometry></visual>
    <collision><geometry><mesh filename="meshes/gripper/link_1.obj"/></geometry></collision>
  </link>
  <joint name="right_1_Joint" type="revolute">
    <origin rpy="2.5708 0 3.1416" xyz="0 0.030141 0.090147"/><!-- 默认张开: roll +1 -->
    <parent link="gripper_base"/>
    <child link="right_1_link"/>
    <axis xyz="1 0 0"/>
    <limit effort="1000" lower="0" upper="1" velocity="2.0"/>
    <mimic joint="gripper_joint" multiplier="1" offset="0"/>
  </joint>

  <link name="right_up_link">
    <inertial>
      <origin xyz="8.69814518862609E-11 0.0124078988097266 -0.00725256147435587"/>
      <mass value="0.014692561982481"/>
      <inertia ixx="2.35283034039115E-06" ixy="3.49796366331572E-14" ixz="-4.72158801523363E-15"
               iyy="5.89429454773258E-07" iyz="7.05860796343296E-07" izz="2.07228020362137E-06"/>
    </inertial>
    <visual><geometry><mesh filename="meshes/gripper/up_link.obj"/></geometry></visual>
    <collision><geometry><mesh filename="meshes/gripper/up_link.obj"/></geometry></collision>
  </link>
  <joint name="right_up_Joint" type="revolute">
    <origin xyz="0 0.054804 -0.0046413" rpy="-1 0 0"/><!-- 默认张开: roll -1 (axis=-X) -->
    <parent link="right_1_link"/>
    <child link="right_up_link"/>
    <axis xyz="-1 0 0"/>
    <limit effort="1000" lower="0" upper="1" velocity="2.0"/>
    <mimic joint="gripper_joint" multiplier="1" offset="0"/>
  </joint>

  <link name="right_Pad_link">
    <inertial>
      <origin xyz="-3.83777509579761E-08 0.00303135276101582 0.0028336970357949"/>
      <mass value="0.0183171479595721"/>
      <inertia ixx="2.35683098270332E-06" ixy="-4.7353365844279E-12" ixz="-9.31433971475514E-13"
               iyy="9.08136064346118E-07" iyz="-1.55873132053129E-08" izz="3.18448591439082E-06"/>
    </inertial>
    <visual><geometry><mesh filename="meshes/gripper/pad_link.obj"/></geometry></visual>
    <collision><geometry><mesh filename="meshes/gripper/pad_link.obj"/></geometry></collision>
  </link>
  <joint name="right_Pad_Joint" type="fixed">
    <origin xyz="0 0.04125 -0.02425"/>
    <parent link="right_up_link"/>
    <child link="right_Pad_link"/>
  </joint>

  <!-- ================= END EFFECTOR ================= -->
  <link name="eef"/>
  <joint name="eef_joint" type="fixed">
    <parent link="gripper_base"/>
    <child link="eef"/>
    <origin xyz="0 0 0.19"/>
  </joint>
</robot>
