<?xml version="1.0" encoding="utf-8"?>

<robot name="xarm6_with_gripper_v1">
  <link name="world"/>
  <joint name="world_joint" type="fixed">
    <parent link="world"/>
    <child link="link_base"/>
    <origin rpy="0 0 0" xyz="0 0 0"/>
  </joint>
 
  <material name="Black">
    <color rgba="0.0 0.0 0.0 1.0"/>
  </material>
  <material name="Red">
    <color rgba="0.8 0.0 0.0 1.0"/>
  </material>
  <material name="White">
    <color rgba="1.0 1.0 1.0 1.0"/>
  </material>
  <material name="Silver">
    <color rgba="0.753 0.753 0.753 1.0"/>
  </material>
  <material name="MaterialFromMTL">
    <color rgba="0.8 0.8 0.8 1.0"/>
    <specular rgb="0.8 0.8 0.8"/>
    <ambient rgb="0.8 0.8 0.8"/>
    <diffuse rgb="0.8 0.8 0.8"/>
  </material>
  <material name="MaterialFromMTL2">
    <color rgba="0.8 0.8 0.8 1.0"/>
    <specular rgb="0.5 0.5 0.5"/>
    <ambient rgb="1.0 1.0 1.0"/>
    <diffuse rgb="0.8 0.8 0.8"/>
  </material>
  
  <!-- Base link -->
  <link name="link_base">
    <visual>
      <geometry>
        <mesh filename="visual/base.stl"/>
      </geometry>
      <origin rpy="0 0 0" xyz="0 0 0"/>
      <material name="MaterialFromMTL"/>
    </visual>
    <collision>
      <geometry>
        <mesh filename="collision/base_vhacd.obj"/>
      </geometry>
      <origin rpy="0 0 0" xyz="0 0 0"/>
    </collision>
    <inertial>
      <origin rpy="0 0 0" xyz="0.0 0.0 0.09103"/>
      <mass value="2.7"/>
      <inertia ixx="0.00494875" ixy="-3.5E-06" ixz="1.25E-05" iyy="0.00494174" iyz="1.67E-06" izz="0.002219"/>
    </inertial>
  </link>
 
  <!-- Link 1 -->
  <link name="link1">
    <visual>
      <geometry>
        <mesh filename="visual/link1.stl"/>
      </geometry>
      <origin rpy="0 0 0" xyz="0 0 0"/>
      <material name="MaterialFromMTL"/>
    </visual>
    <collision>
      <geometry>
        <mesh filename="collision/link1_vhacd.obj"/>
      </geometry>
      <origin rpy="0 0 0" xyz="0 0 0"/>
    </collision>
    <inertial>
      <origin rpy="0 0 0" xyz="-0.002 0.02692 -0.01332"/>
      <mass value="2.16"/>
      <inertia ixx="0.00539427" ixy="1.095E-05" ixz="1.635E-06" iyy="0.0048979" iyz="0.000793" izz="0.00311573"/>
    </inertial>
  </link>

  <joint name="joint1" type="revolute">
    <safety_controller k_position="100.0" k_velocity="40.0" soft_lower_limit="-6.28318530718" soft_upper_limit="6.28318530718"/>
    <parent link="link_base"/>
    <child link="link1"/>
    <origin rpy="0 0 0" xyz="0 0 0.267"/>
    <axis xyz="0 0 1"/>
    <limit effort="50.0" lower="-6.28318530718" upper="6.28318530718" velocity="3.1415"/>
    <dynamics damping="10.0" friction="1.0"/>
  </joint>
  
  <!-- Link 2 -->
  <link name="link2">
    <visual>
      <geometry>
        <mesh filename="visual/link2.stl"/>
      </geometry>
      <origin rpy="0 0 0" xyz="0 0 0"/>
      <material name="MaterialFromMTL"/>
    </visual>
    <collision>
      <geometry>
        <mesh filename="collision/link2_vhacd2.obj"/>
      </geometry>
      <origin rpy="0 0 0" xyz="0 0 0"/>
    </collision>
    <inertial>
      <origin rpy="0 0 0" xyz="0.03531 -0.21398 0.03386"/>
      <mass value="1.71"/>
      <inertia ixx="0.0248674" ixy="-0.00430651" ixz="-0.00067797" iyy="0.00485548" iyz="0.00457245" izz="0.02387827"/>
    </inertial>
  </link>
  
  <joint name="joint2" type="revolute">
    <safety_controller k_position="100.0" k_velocity="40.0" soft_lower_limit="-2.059" soft_upper_limit="2.059"/>
    <parent link="link1"/>
    <child link="link2"/>
    <origin rpy="-1.5708 0 0" xyz="0 0 0"/>
    <axis xyz="0 0 1"/>
    <limit effort="50.0" lower="-2.059" upper="2.0944" velocity="3.1415"/>
    <dynamics damping="10.0" friction="1.0"/>
  </joint>
  
  <!-- Link 3 -->
  <link name="link3">
    <visual>
      <geometry>
        <mesh filename="visual/link3.stl"/>
      </geometry>
      <origin rpy="0 0 0" xyz="0 0 0"/>
      <material name="MaterialFromMTL"/>
    </visual>
    <collision>
      <geometry>
        <mesh filename="collision/link3_vhacd.obj"/>
      </geometry>
      <origin rpy="0 0 0" xyz="0 0 0"/>
    </collision>
    <inertial>
      <origin rpy="0 0 0" xyz="0.06781 0.10749 0.01457"/>
      <mass value="1.384"/>
      <inertia ixx="0.0053694" ixy="0.0014185" ixz="-0.00092094" iyy="0.0032423" iyz="-0.00169178" izz="0.00501731"/>
    </inertial>
  </link>
  
  <joint name="joint3" type="revolute">
    <safety_controller k_position="100.0" k_velocity="40.0" soft_lower_limit="-3.8" soft_upper_limit="0.19198"/>
    <parent link="link2"/>
    <child link="link3"/>
    <origin rpy="0 0 0" xyz="0.0535 -0.2845 0"/>
    <axis xyz="0 0 1"/>
    <limit effort="32.0" lower="-3.8" upper="0.19198" velocity="3.1415"/>
    <dynamics damping="10.0" friction="1.0"/>
  </joint>
  
  <!-- Link 4 -->
  <link name="link4">
    <visual>
      <geometry>
        <mesh filename="visual/link4.stl"/>
      </geometry>
      <origin rpy="0 0 0" xyz="0 0 0"/>
      <material name="MaterialFromMTL"/>
    </visual>
    <collision>
      <geometry>
        <mesh filename="collision/link4_vhacd.obj"/>
      </geometry>
      <origin rpy="0 0 0" xyz="0 0 0"/>
    </collision>
    <inertial>
      <origin rpy="0 0 0" xyz="-0.00021 0.02578 -0.02538"/>
      <mass value="1.115"/>
      <inertia ixx="0.00439263" ixy="5.028E-05" ixz="1.374E-05" iyy="0.0040077" iyz="0.00045338" izz="0.00110321"/>
    </inertial>
  </link>
  
  <joint name="joint4" type="revolute">
    <safety_controller k_position="100.0" k_velocity="40.0" soft_lower_limit="-6.28318530718" soft_upper_limit="6.28318530718"/>
    <parent link="link3"/>
    <child link="link4"/>
    <origin rpy="-1.5708 0 0" xyz="0.0775 0.3425 0"/>
    <axis xyz="0 0 1"/>
    <limit effort="32.0" lower="-6.28318530718" upper="6.28318530718" velocity="3.1415"/>
    <dynamics damping="10.0" friction="1.0"/>
  </joint>
  
  <!-- Link 5 -->
  <link name="link5">
    <visual>
      <geometry>
        <mesh filename="visual/link5.stl"/>
      </geometry>
      <origin rpy="0 0 0" xyz="0 0 0"/>
      <material name="MaterialFromMTL"/>
    </visual>
    <collision>
      <geometry>
        <mesh filename="collision/link5_vhacd.obj"/>
      </geometry>
      <origin rpy="0 0 0" xyz="0 0 0"/>
    </collision>
    <inertial>
      <origin rpy="0 0 0" xyz="0.05428 0.01781 0.00543"/>
      <mass value="1.275"/>
      <inertia ixx="0.001202758" ixy="0.000492428" ixz="-0.00039147" iyy="0.0022876" iyz="-1.235E-04" izz="0.0026866"/>
    </inertial>
  </link>
  
  <joint name="joint5" type="revolute">
    <safety_controller k_position="100.0" k_velocity="40.0" soft_lower_limit="-1.69297" soft_upper_limit="2.094395"/>
    <parent link="link4"/>
    <child link="link5"/>
    <origin rpy="1.5708 0 0" xyz="0 0 0"/>
    <axis xyz="0 0 1"/>
    <limit effort="32.0" lower="-1.69297" upper="2.094395" velocity="3.1415"/>
    <dynamics damping="10.0" friction="1.0"/>
  </joint>
  
  <!-- Link 6 -->
  <link name="link6">
    <visual>
      <geometry>
        <mesh filename="visual/link6.stl"/>
      </geometry>
      <origin rpy="0 0 0" xyz="0 0 0"/>
      <material name="MaterialFromMTL"/>
    </visual>
    <collision>
      <geometry>
        <mesh filename="collision/link6_vhacd.obj"/>
      </geometry>
      <origin rpy="0 0 0" xyz="0 0 0"/>
    </collision>
    <inertial>
      <origin rpy="0 0 0" xyz="0 0.00064 -0.00952"/>
      <mass value="0.1"/>
      <inertia ixx="2.5E-05" ixy="0" ixz="0" iyy="2.36E-05" iyz="0" izz="2.58E-05"/>
    </inertial>
  </link>
  
  <joint name="joint6" type="revolute">
    <safety_controller k_position="100.0" k_velocity="40.0" soft_lower_limit="-6.28318530718" soft_upper_limit="6.28318530718"/>
    <parent link="link5"/>
    <child link="link6"/>
    <origin rpy="-1.5708 0 0" xyz="0.076 0.097 0"/>
    <axis xyz="0 0 1"/>
    <limit effort="20.0" lower="-6.28318530718" upper="6.28318530718" velocity="3.1415"/>
    <dynamics damping="10.0" friction="1.0"/>
  </joint>
  
  <!-- TCP link (for the standard gripper) -->
  <link name="link_tcp">
      <inertial>
          <origin xyz="0 0 0" rpy="0 0 0"/>
          <mass value="0.00000001"/>
          <inertia ixx="0.000001" ixy="0" ixz="0" iyy="0.000001" iyz="0" izz="0.000001"/>
      </inertial>
  </link>
  <joint name="joint_tcp" type="fixed">
      <parent link="link6"/>
      <child link="link_tcp"/>
      <origin xyz="0 0 0.082" rpy="0 0 0"/> <!-- Adjust this based on actual TCP -->
  </joint>

  <!-- xArm Gripper Base Link -->
  <link name="xarm_gripper_base_link">
    <visual>
      <origin rpy="0 0 0" xyz="0 0 0"/>
      <geometry>
        <mesh filename="meshes/gripper/xarm/base_link.stl" scale="1 1 1"/>
      </geometry>
      <material name="Silver"/>
    </visual>
    <collision>
      <origin rpy="0 0 0" xyz="0 0 0"/>
      <geometry>
        <mesh filename="meshes/gripper/xarm/base_link.stl" scale="1 1 1"/>
      </geometry>
    </collision>
    <inertial>
      <origin rpy="0 0 0" xyz="0 0 0.022"/>
      <mass value="0.2"/>
      <inertia ixx="0.0002" ixy="0" ixz="0" iyy="0.0002" iyz="0" izz="0.0001"/>
    </inertial>
  </link>

  <joint name="link6_to_gripper_base_link_fixed" type="fixed">
    <parent link="link6"/>
    <child link="xarm_gripper_base_link"/>
    <origin rpy="0 0 0" xyz="0 0 0.082"/>
  </joint>

  <!-- Left Finger Assembly -->
  <link name="left_outer_knuckle">
    <visual>
      <origin rpy="0 0 0" xyz="0 0 0"/>
      <geometry>
        <mesh filename="visual/left_outer_knuckle.stl"/>
      </geometry>
      <material name="Silver"/>
    </visual>
    <collision>
      <origin rpy="0 0 0" xyz="0 0 0"/>
      <geometry>
        <mesh filename="collision/left_outer_knuckle_vhacd.obj"/>
      </geometry>
    </collision>
    <inertial>
      <origin rpy="0 0 0" xyz="0 0.01 0.01"/>
      <mass value="0.02"/>
      <inertia ixx="1e-05" ixy="0" ixz="0" iyy="1e-05" iyz="0" izz="1e-05"/>
    </inertial>
  </link>
  <joint name="left_outer_knuckle_joint" type="revolute">
    <parent link="xarm_gripper_base_link"/>
    <child link="left_outer_knuckle"/>
    <origin rpy="0 0 0" xyz="0 0.0213 0.022"/>
    <axis xyz="1 0 0"/>
    <limit effort="10" lower="0" upper="1.5708" velocity="0.5"/>
    <dynamics damping="0.5" friction="0.2"/>
    <!-- Mimic removed -->
  </joint>

  <link name="left_finger">
    <visual>
      <origin rpy="0 0 0" xyz="0 0 0"/>
      <geometry>
        <mesh filename="visual/left_finger.stl"/>
      </geometry>
      <material name="Silver"/>
    </visual>
    <collision>
      <origin rpy="0 0 0" xyz="0 0 0"/>
      <geometry>
        <mesh filename="collision/left_finger_vhacd.obj"/>
      </geometry>
    </collision>
    <inertial>
      <origin rpy="0 0 0" xyz="0 0.01 0.03"/>
      <mass value="0.05"/>
      <inertia ixx="2e-05" ixy="0" ixz="0" iyy="2e-05" iyz="0" izz="1e-05"/>
    </inertial>
  </link>
  <joint name="left_finger_joint" type="revolute">
    <parent link="left_outer_knuckle"/>
    <child link="left_finger"/>
    <origin rpy="0 0 0" xyz="0 0.036 0"/>
    <axis xyz="-1 0 0"/> <!-- Axis aligned with right_finger_joint after its correction -->
    <limit effort="10" lower="-1.5708" upper="0" velocity="0.5"/>
    <dynamics damping="0.5" friction="0.3"/> <!-- Original V1 had higher friction here -->
    <!-- Mimic removed -->
  </joint>

  <link name="left_inner_knuckle">
    <visual>
      <origin rpy="0 0 0" xyz="0 0 0"/>
      <geometry>
        <mesh filename="visual/left_inner_knuckle.stl"/>
      </geometry>
      <material name="Silver"/>
    </visual>
    <collision>
      <origin rpy="0 0 0" xyz="0 0 0"/>
      <geometry>
        <mesh filename="collision/left_inner_knuckle_vhacd.obj"/>
      </geometry>
    </collision>
    <inertial>
      <origin rpy="0 0 0" xyz="0 0.01 0.01"/>
      <mass value="0.02"/>
      <inertia ixx="1e-05" ixy="0" ixz="0" iyy="1e-05" iyz="0" izz="1e-05"/>
    </inertial>
  </link>
  <joint name="left_inner_knuckle_joint" type="revolute">
    <parent link="xarm_gripper_base_link"/>
    <child link="left_inner_knuckle"/>
    <origin rpy="0 0 0" xyz="0 0.0126 0.047"/>
    <axis xyz="1 0 0"/>
    <limit effort="10" lower="0" upper="1.5708" velocity="0.5"/>
    <dynamics damping="0.5" friction="0.2"/>
    <!-- Mimic removed -->
  </joint>

  <!-- Right Finger Assembly -->
  <link name="right_outer_knuckle">
    <visual>
      <origin rpy="0 0 0" xyz="0 0 0"/>
      <geometry>
        <mesh filename="visual/right_outer_knuckle.stl"/>
      </geometry>
      <material name="Silver"/>
    </visual>
    <collision>
      <origin rpy="0 0 0" xyz="0 0 0"/>
      <geometry>
        <mesh filename="collision/right_outer_knuckle_vhacd.obj"/>
      </geometry>
    </collision>
    <inertial>
      <origin rpy="0 0 0" xyz="0 -0.01 0.01"/>
      <mass value="0.02"/>
      <inertia ixx="1e-05" ixy="0" ixz="0" iyy="1e-05" iyz="0" izz="1e-05"/>
    </inertial>
  </link>
  <joint name="right_outer_knuckle_joint" type="revolute">
    <parent link="xarm_gripper_base_link"/>
    <child link="right_outer_knuckle"/>
    <origin rpy="0 0 0" xyz="0 -0.0213 0.022"/>
    <axis xyz="1 0 0"/> <!-- Axis consistent with left_outer_knuckle_joint -->
    <limit effort="10" lower="0" upper="1.5708" velocity="0.5"/>
    <dynamics damping="0.5" friction="0.2"/>
    <!-- Mimic removed -->
  </joint>

  <link name="right_finger">
    <visual>
      <origin rpy="0 0 0" xyz="0 0 0"/>
      <geometry>
        <mesh filename="visual/right_finger.stl"/>
      </geometry>
      <material name="Silver"/>
    </visual>
    <collision>
      <origin rpy="0 0 0" xyz="0 0 0"/>
      <geometry>
        <mesh filename="collision/right_finger_vhacd.obj"/>
      </geometry>
    </collision>
    <inertial>
      <origin rpy="0 0 0" xyz="0 -0.01 0.03"/>
      <mass value="0.05"/>
      <inertia ixx="2e-05" ixy="0" ixz="0" iyy="2e-05" iyz="0" izz="1e-05"/>
    </inertial>
  </link>
  <joint name="right_finger_joint" type="revolute">
    <parent link="right_outer_knuckle"/>
    <child link="right_finger"/>
    <origin rpy="0 0 0" xyz="0 -0.036 0"/>
    <axis xyz="-1 0 0"/> <!-- Axis consistent with left_finger_joint's mimic logic -->
    <limit effort="10" lower="-1.5708" upper="0" velocity="0.5"/>
    <dynamics damping="0.5" friction="0.2"/> <!-- Friction harmonized -->
    <!-- Mimic removed -->
  </joint>

  <link name="right_inner_knuckle">
    <visual>
      <origin rpy="0 0 0" xyz="0 0 0"/>
      <geometry>
        <mesh filename="visual/right_inner_knuckle.stl"/>
      </geometry>
      <material name="Silver"/>
    </visual>
    <collision>
      <origin rpy="0 0 0" xyz="0 0 0"/>
      <geometry>
        <mesh filename="collision/right_inner_knuckle_vhacd.obj"/>
      </geometry>
    </collision>
    <inertial>
      <origin rpy="0 0 0" xyz="0 -0.01 0.01"/>
      <mass value="0.02"/>
      <inertia ixx="1e-05" ixy="0" ixz="0" iyy="1e-05" iyz="0" izz="1e-05"/>
    </inertial>
  </link>
  <joint name="right_inner_knuckle_joint" type="revolute">
    <parent link="xarm_gripper_base_link"/>
    <child link="right_inner_knuckle"/>
    <origin rpy="0 0 0" xyz="0 -0.0126 0.047"/>
    <axis xyz="1 0 0"/> <!-- Axis consistent with left_inner_knuckle_joint -->
    <limit effort="10" lower="0" upper="1.5708" velocity="0.5"/>
    <dynamics damping="0.5" friction="0.2"/>
    <!-- Mimic removed -->
  </joint>

</robot> 