<?xml version="1.0" ?>
<!-- =================================================================================== -->
<!-- |    This document was autogenerated by xacro from xarm_device.urdf.xacro         | -->
<!-- |    EDITING THIS FILE BY HAND IS NOT RECOMMENDED                                 | -->
<!-- =================================================================================== -->
<robot name="UF_ROBOT">
  <!-- Insert at the beginning of xarm_device_macro.xacro -->
  <material name="Black">
    <color rgba="0.0 0.0 0.0 1.0"/>
  </material>
  <material name="Red">
    <color rgba="0.8 0.0 0.0 1.0"/>
  </material>
  <material name="White">
    <color rgba="1.0 1.0 1.0 1.0"/>
  </material>
  <material name="Silver">
    <color rgba="0.753 0.753 0.753 1.0"/>
  </material>
  <link name="world"/>
  <joint name="world_joint" type="fixed">
    <parent link="world"/>
    <child link="link_base"/>
    <origin rpy="0 0 0" xyz="0 0 0"/>
  </joint>
  <ros2_control name="uf_robot_hardware/UFRobotSystemHardware" type="system">
    <hardware>
      <plugin>uf_robot_hardware/UFRobotSystemHardware</plugin>
      <param name="hw_ns">xarm</param>
      <param name="velocity_control">False</param>
      <param name="prefix">P</param>
      <param name="robot_ip">R</param>
      <param name="report_type">normal</param>
      <param name="dof">6</param>
      <param name="baud_checkset">True</param>
      <param name="default_gripper_baud">2000000</param>
      <param name="robot_type">xarm</param>
      <param name="add_gripper">True</param>
      <param name="add_bio_gripper">False</param>
      <!-- fake -->
      <!-- <plugin>fake_components/GenericSystem</plugin> -->
      <!-- gazebo -->
      <!-- <plugin>gazebo_ros2_control/GazeboSystem</plugin> -->
      <!-- real xarm -->
      <!-- <plugin>uf_robot_hardware/UFRobotSystemHardware</plugin> -->
    </hardware>
    <joint name="joint1">
      <command_interface name="position">
        <param name="min">-6.283185307179586</param>
        <param name="max">6.283185307179586</param>
      </command_interface>
      <command_interface name="velocity">
        <param name="min">-3.14</param>
        <param name="max">3.14</param>
      </command_interface>
      <state_interface name="position"/>
      <state_interface name="velocity"/>
      <!-- <state_interface name="effort"/> -->
    </joint>
    <joint name="joint2">
      <command_interface name="position">
        <param name="min">-2.059</param>
        <param name="max">2.0944</param>
      </command_interface>
      <command_interface name="velocity">
        <param name="min">-3.14</param>
        <param name="max">3.14</param>
      </command_interface>
      <state_interface name="position"/>
      <state_interface name="velocity"/>
      <!-- <state_interface name="effort"/> -->
    </joint>
    <joint name="joint3">
      <command_interface name="position">
        <param name="min">-3.927</param>
        <param name="max">0.19198</param>
      </command_interface>
      <command_interface name="velocity">
        <param name="min">-3.14</param>
        <param name="max">3.14</param>
      </command_interface>
      <state_interface name="position"/>
      <state_interface name="velocity"/>
      <!-- <state_interface name="effort"/> -->
    </joint>
    <joint name="joint4">
      <command_interface name="position">
        <param name="min">-6.283185307179586</param>
        <param name="max">6.283185307179586</param>
      </command_interface>
      <command_interface name="velocity">
        <param name="min">-3.14</param>
        <param name="max">3.14</param>
      </command_interface>
      <state_interface name="position"/>
      <state_interface name="velocity"/>
      <!-- <state_interface name="effort"/> -->
    </joint>
    <joint name="joint5">
      <command_interface name="position">
        <param name="min">-1.69297</param>
        <param name="max">3.141592653589793</param>
      </command_interface>
      <command_interface name="velocity">
        <param name="min">-3.14</param>
        <param name="max">3.14</param>
      </command_interface>
      <state_interface name="position"/>
      <state_interface name="velocity"/>
      <!-- <state_interface name="effort"/> -->
    </joint>
    <joint name="joint6">
      <command_interface name="position">
        <param name="min">-6.283185307179586</param>
        <param name="max">6.283185307179586</param>
      </command_interface>
      <command_interface name="velocity">
        <param name="min">-3.14</param>
        <param name="max">3.14</param>
      </command_interface>
      <state_interface name="position"/>
      <state_interface name="velocity"/>
      <!-- <state_interface name="effort"/> -->
    </joint>
  </ros2_control>
  <link name="link_base">
    <inertial>
      <origin rpy="0 0 0" xyz="0.0 0.0 0.09103"/>
      <mass value="2.7"/>
      <inertia ixx="0.00494875" ixy="-3.5E-06" ixz="1.25E-05" iyy="0.00494174" iyz="1.67E-06" izz="0.002219"/>
    </inertial>
    <visual>
      <geometry>
        <mesh filename="package://xarm_description/meshes/xarm6/visual/link_base.dae"/>
      </geometry>
      <origin rpy="0 0 0" xyz="0 0 0"/>
    </visual>
    <collision>
      <geometry>
        <mesh filename="package://xarm_description/meshes/xarm6/visual/link_base.stl"/>
      </geometry>
      <origin rpy="0 0 0" xyz="0 0 0"/>
    </collision>
  </link>
  <link name="link1">
    <inertial>
      <origin rpy="0 0 0" xyz="0.00022 0.02951 -0.0124"/>
      <mass value="2.3814"/>
      <inertia ixx="0.0058562" ixy="-1.79e-05" ixz="3.55e-06" iyy="0.0050316" iyz="-0.000888336" izz="0.003536652"/>
    </inertial>
    <visual>
      <geometry>
        <mesh filename="package://xarm_description/meshes/xarm6/visual/link1.dae"/>
      </geometry>
      <origin rpy="0 0 0" xyz="0 0 0"/>
    </visual>
    <collision>
      <geometry>
        <mesh filename="package://xarm_description/meshes/xarm6/visual/link1.stl"/>
      </geometry>
      <origin rpy="0 0 0" xyz="0 0 0"/>
    </collision>
  </link>
  <joint name="joint1" type="revolute">
    <parent link="link_base"/>
    <child link="link1"/>
    <origin rpy="0 0 0" xyz="0 0 0.267"/>
    <axis xyz="0 0 1"/>
    <limit effort="50.0" lower="-6.283185307179586" upper="6.283185307179586" velocity="3.14"/>
    <dynamics damping="1.0" friction="1.0"/>
  </joint>
  <link name="link2">
    <inertial>
      <origin rpy="0 0 0" xyz="0.03881 -0.22783 0.03496"/>
      <mass value="2.2675"/>
      <inertia ixx="0.028315776" ixy="0.005" ixz="0.00066546" iyy="0.0058" iyz="-0.0045741" izz="0.0273447"/>
    </inertial>
    <visual>
      <geometry>
        <mesh filename="package://xarm_description/meshes/xarm6/visual/link2.dae"/>
      </geometry>
      <origin rpy="0 0 0" xyz="0 0 0"/>
    </visual>
    <collision>
      <geometry>
        <mesh filename="package://xarm_description/meshes/xarm6/visual/link2.stl"/>
      </geometry>
      <origin rpy="0 0 0" xyz="0 0 0"/>
    </collision>
  </link>
  <joint name="joint2" type="revolute">
    <parent link="link1"/>
    <child link="link2"/>
    <origin rpy="-1.5708 0 0" xyz="0 0 0"/>
    <axis xyz="0 0 1"/>
    <limit effort="50.0" lower="-2.059" upper="2.0944" velocity="3.14"/>
    <dynamics damping="1.0" friction="1.0"/>
  </joint>
  <link name="link3">
    <inertial>
      <origin rpy="0 0 0" xyz="0.07041 0.11631 0.0107"/>
      <mass value="1.875"/>
      <inertia ixx="0.0063483" ixy="-0.0015397" ixz="0.00096858" iyy="0.00379758" iyz="0.00186567" izz="0.00595768"/>
    </inertial>
    <visual>
      <geometry>
        <mesh filename="package://xarm_description/meshes/xarm6/visual/link3.dae"/>
      </geometry>
      <origin rpy="0 0 0" xyz="0 0 0"/>
    </visual>
    <collision>
      <geometry>
        <mesh filename="package://xarm_description/meshes/xarm6/visual/link3.stl"/>
      </geometry>
      <origin rpy="0 0 0" xyz="0 0 0"/>
    </collision>
  </link>
  <joint name="joint3" type="revolute">
    <parent link="link2"/>
    <child link="link3"/>
    <origin rpy="0 0 0" xyz="0.0535 -0.2845 0"/>
    <axis xyz="0 0 1"/>
    <limit effort="32.0" lower="-3.927" upper="0.19198" velocity="3.14"/>
    <dynamics damping="1.0" friction="1.0"/>
  </joint>
  <link name="link4">
    <inertial>
      <origin rpy="0 0 0" xyz="-0.00018 0.01798 -0.02291"/>
      <mass value="1.3192"/>
      <inertia ixx="0.004896" ixy="-6.925e-06" ixz="-1.418e-05" iyy="0.00445694" iyz="-0.00023186" izz="0.00134332"/>
    </inertial>
    <visual>
      <geometry>
        <mesh filename="package://xarm_description/meshes/xarm6/visual/link4.dae"/>
      </geometry>
      <origin rpy="0 0 0" xyz="0 0 0"/>
    </visual>
    <collision>
      <geometry>
        <mesh filename="package://xarm_description/meshes/xarm6/visual/link4.stl"/>
      </geometry>
      <origin rpy="0 0 0" xyz="0 0 0"/>
    </collision>
  </link>
  <joint name="joint4" type="revolute">
    <parent link="link3"/>
    <child link="link4"/>
    <origin rpy="-1.5708 0 0" xyz="0.0775 0.3425 0"/>
    <axis xyz="0 0 1"/>
    <limit effort="32.0" lower="-6.283185307179586" upper="6.283185307179586" velocity="3.14"/>
    <dynamics damping="1.0" friction="1.0"/>
  </joint>
  <link name="link5">
    <inertial>
      <origin rpy="0 0 0" xyz="0.0651 0.03096 0.00315"/>
      <mass value="1.33854"/>
      <inertia ixx="0.00146378" ixy="-0.000450624" ixz="0.000284306" iyy="0.00184192" iyz="0.000130866" izz="0.002333524"/>
    </inertial>
    <visual>
      <geometry>
        <mesh filename="package://xarm_description/meshes/xarm6/visual/link5.dae"/>
      </geometry>
      <origin rpy="0 0 0" xyz="0 0 0"/>
    </visual>
    <collision>
      <geometry>
        <mesh filename="package://xarm_description/meshes/xarm6/visual/link5.stl"/>
      </geometry>
      <origin rpy="0 0 0" xyz="0 0 0"/>
    </collision>
  </link>
  <joint name="joint5" type="revolute">
    <parent link="link4"/>
    <child link="link5"/>
    <origin rpy="1.5708 0 0" xyz="0 0 0"/>
    <axis xyz="0 0 1"/>
    <limit effort="32.0" lower="-1.69297" upper="3.141592653589793" velocity="3.14"/>
    <dynamics damping="1.0" friction="1.0"/>
  </joint>
  <link name="link6">
    <inertial>
      <origin rpy="0 0 0" xyz="0 -0.00677 -0.01098"/>
      <mass value="0.17"/>
      <inertia ixx="9.3e-05" ixy="-0.0" ixz="-0.0" iyy="5.87e-05" iyz="-3.6e-06" izz="0.000132"/>
    </inertial>
    <visual>
      <geometry>
        <mesh filename="package://xarm_description/meshes/xarm6/visual/link6.dae"/>
      </geometry>
      <origin rpy="0 0 0" xyz="0 0 0"/>
    </visual>
    <collision>
      <geometry>
        <mesh filename="package://xarm_description/meshes/end_tool/collision/end_tool.stl"/>
      </geometry>
      <origin rpy="0 0 0" xyz="0 0 0"/>
    </collision>
  </link>
  <joint name="joint6" type="revolute">
    <parent link="link5"/>
    <child link="link6"/>
    <origin rpy="-1.5708 0 0" xyz="0.076 0.097 0"/>
    <axis xyz="0 0 1"/>
    <limit effort="20.0" lower="-6.283185307179586" upper="6.283185307179586" velocity="3.14"/>
    <dynamics damping="1.0" friction="1.0"/>
  </joint>
  <!-- <link name="${prefix}link_eef" />
    <joint name="${prefix}joint_eef" type="fixed">
      <origin xyz="0 0 0" rpy="0 0 0" />
      <parent link="${prefix}link6" />
      <child link="${prefix}link_eef" />
    </joint> -->
  <transmission name="tran1">
    <type>transmission_interface/SimpleTransmission</type>
    <joint name="joint1">
      <hardwareInterface>hardware_interface/PositionJointInterface</hardwareInterface>
    </joint>
    <actuator name="motor1">
      <hardwareInterface>hardware_interface/PositionJointInterface</hardwareInterface>
      <mechanicalReduction>100</mechanicalReduction>
    </actuator>
  </transmission>
  <transmission name="tran2">
    <type>transmission_interface/SimpleTransmission</type>
    <joint name="joint2">
      <hardwareInterface>hardware_interface/PositionJointInterface</hardwareInterface>
    </joint>
    <actuator name="motor2">
      <hardwareInterface>hardware_interface/PositionJointInterface</hardwareInterface>
      <mechanicalReduction>100</mechanicalReduction>
    </actuator>
  </transmission>
  <transmission name="tran3">
    <type>transmission_interface/SimpleTransmission</type>
    <joint name="joint3">
      <hardwareInterface>hardware_interface/PositionJointInterface</hardwareInterface>
    </joint>
    <actuator name="motor3">
      <hardwareInterface>hardware_interface/PositionJointInterface</hardwareInterface>
      <mechanicalReduction>100</mechanicalReduction>
    </actuator>
  </transmission>
  <transmission name="tran4">
    <type>transmission_interface/SimpleTransmission</type>
    <joint name="joint4">
      <hardwareInterface>hardware_interface/PositionJointInterface</hardwareInterface>
    </joint>
    <actuator name="motor4">
      <hardwareInterface>hardware_interface/PositionJointInterface</hardwareInterface>
      <mechanicalReduction>100</mechanicalReduction>
    </actuator>
  </transmission>
  <transmission name="tran5">
    <type>transmission_interface/SimpleTransmission</type>
    <joint name="joint5">
      <hardwareInterface>hardware_interface/PositionJointInterface</hardwareInterface>
    </joint>
    <actuator name="motor5">
      <hardwareInterface>hardware_interface/PositionJointInterface</hardwareInterface>
      <mechanicalReduction>100</mechanicalReduction>
    </actuator>
  </transmission>
  <transmission name="tran6">
    <type>transmission_interface/SimpleTransmission</type>
    <joint name="joint6">
      <hardwareInterface>hardware_interface/PositionJointInterface</hardwareInterface>
    </joint>
    <actuator name="motor6">
      <hardwareInterface>hardware_interface/PositionJointInterface</hardwareInterface>
      <mechanicalReduction>100</mechanicalReduction>
    </actuator>
  </transmission>
  <gazebo reference="link_base">
    <selfCollide>true</selfCollide>
  </gazebo>
  <gazebo reference="link1">
    <selfCollide>true</selfCollide>
  </gazebo>
  <gazebo reference="link2">
    <selfCollide>true</selfCollide>
  </gazebo>
  <gazebo reference="link3">
    <selfCollide>true</selfCollide>
  </gazebo>
  <gazebo reference="link4">
    <selfCollide>true</selfCollide>
  </gazebo>
  <gazebo reference="link5">
    <selfCollide>true</selfCollide>
  </gazebo>
  <gazebo reference="link6">
    <selfCollide>true</selfCollide>
  </gazebo>
  <link name="link_eef"/>
  <joint name="joint_eef" type="fixed">
    <origin rpy="0 0 0" xyz="0 0 0"/>
    <parent link="link6"/>
    <child link="link_eef"/>
  </joint>
  <joint name="gripper_fix" type="fixed">
    <parent link="link_eef"/>
    <child link="xarm_gripper_base_link"/>
    <origin rpy="0 0 0" xyz="0 0 0"/>
  </joint>
  <link name="xarm_gripper_base_link">
    <inertial>
      <origin rpy="0 0 0" xyz="-0.00065489 -0.0018497 0.048028"/>
      <mass value="0.54156"/>
      <inertia ixx="0.00047106" ixy="-3.9292E-07" ixz="-2.6537E-06" iyy="0.00033072" iyz="1.0975E-05" izz="0.00025642"/>
    </inertial>
    <visual>
      <geometry>
        <mesh filename="package://xarm_description/meshes/gripper/xarm/base_link.stl"/>
      </geometry>
      <origin rpy="0 0 0" xyz="0 0 0"/>
      <material name="White"/>
    </visual>
    <collision>
      <geometry>
        <mesh filename="package://xarm_description/meshes/gripper/xarm/base_link.stl"/>
      </geometry>
      <origin rpy="0 0 0" xyz="0 0 0"/>
    </collision>
  </link>
  <link name="left_outer_knuckle">
    <inertial>
      <origin rpy="0 0 0" xyz="2.9948E-14 0.021559 0.015181"/>
      <mass value="0.033618"/>
      <inertia ixx="1.9111E-05" ixy="-1.8803E-17" ixz="-1.1002E-17" iyy="6.6256E-06" iyz="-7.3008E-06" izz="1.3185E-05"/>
    </inertial>
    <visual>
      <geometry>
        <mesh filename="package://xarm_description/meshes/gripper/xarm/left_outer_knuckle.dae"/>
      </geometry>
      <origin rpy="0 0 0" xyz="0 0 0"/>
    </visual>
    <collision>
      <geometry>
        <mesh filename="package://xarm_description/meshes/gripper/xarm/left_outer_knuckle.stl"/>
      </geometry>
      <origin rpy="0 0 0" xyz="0 0 0"/>
    </collision>
  </link>
  <joint name="drive_joint" type="revolute">
    <origin rpy="0 0 0" xyz="0 0.035 0.059098"/>
    <parent link="xarm_gripper_base_link"/>
    <child link="left_outer_knuckle"/>
    <axis xyz="1 0 0"/>
    <limit effort="50" lower="0" upper="0.85" velocity="2"/>
  </joint>
  <link name="left_finger">
    <inertial>
      <origin rpy="0 0 0" xyz="-2.4536E-14 -0.016413 0.029258"/>
      <mass value="0.048304"/>
      <inertia ixx="1.7493E-05" ixy="4.2156E-19" ixz="-6.9164E-18" iyy="1.7225E-05" iyz="-4.6433E-06" izz="5.1466E-06"/>
    </inertial>
    <visual>
      <geometry>
        <mesh filename="package://xarm_description/meshes/gripper/xarm/left_finger.dae"/>
      </geometry>
      <origin rpy="0 0 0" xyz="0 0 0"/>
    </visual>
    <collision>
      <geometry>
        <mesh filename="package://xarm_description/meshes/gripper/xarm/left_finger.stl"/>
      </geometry>
      <origin rpy="0 0 0" xyz="0 0 0"/>
    </collision>
  </link>
  <joint name="left_finger_joint" type="revolute">
    <origin rpy="0 0 0" xyz="0 0.035465 0.042039"/>
    <parent link="left_outer_knuckle"/>
    <child link="left_finger"/>
    <axis xyz="-1 0 0"/>
    <limit effort="50" lower="0" upper="0.85" velocity="2"/>
    <mimic joint="drive_joint" multiplier="1" offset="0"/>
  </joint>
  <link name="left_inner_knuckle">
    <inertial>
      <origin rpy="0 0 0" xyz="1.86600784687907E-06 0.0220467847633621 0.0261334672830885"/>
      <mass value="0.0230125781256706"/>
      <inertia ixx="6.09490024271906E-06" ixy="-6.06651326160071E-11" ixz="-7.19102670500635E-11" iyy="6.01955084375188E-06" iyz="2.75316812991721E-06" izz="5.07862004479903E-06"/>
    </inertial>
    <visual>
      <geometry>
        <mesh filename="package://xarm_description/meshes/gripper/xarm/left_inner_knuckle.dae"/>
      </geometry>
      <origin rpy="0 0 0" xyz="0 0 0"/>
    </visual>
    <collision>
      <geometry>
        <mesh filename="package://xarm_description/meshes/gripper/xarm/left_inner_knuckle.stl"/>
      </geometry>
      <origin rpy="0 0 0" xyz="0 0 0"/>
    </collision>
  </link>
  <joint name="left_inner_knuckle_joint" type="revolute">
    <origin rpy="0 0 0" xyz="0 0.02 0.074098"/>
    <parent link="xarm_gripper_base_link"/>
    <child link="left_inner_knuckle"/>
    <axis xyz="1 0 0"/>
    <limit effort="50" lower="0" upper="0.85" velocity="2"/>
    <mimic joint="drive_joint" multiplier="1" offset="0"/>
  </joint>
  <link name="right_outer_knuckle">
    <inertial>
      <origin rpy="0 0 0" xyz="-3.1669E-14 -0.021559 0.015181"/>
      <mass value="0.033618"/>
      <inertia ixx="1.9111E-05" ixy="1.8789E-17" ixz="-1.0986E-17" iyy="6.6256E-06" iyz="-7.3008E-06" izz="1.3185E-05"/>
    </inertial>
    <visual>
      <geometry>
        <mesh filename="package://xarm_description/meshes/gripper/xarm/right_outer_knuckle.dae"/>
      </geometry>
      <origin rpy="0 0 0" xyz="0 0 0"/>
    </visual>
    <collision>
      <geometry>
        <mesh filename="package://xarm_description/meshes/gripper/xarm/right_outer_knuckle.stl"/>
      </geometry>
      <origin rpy="0 0 0" xyz="0 0 0"/>
    </collision>
  </link>
  <joint name="right_outer_knuckle_joint" type="revolute">
    <origin rpy="0 0 0" xyz="0 -0.035 0.059098"/>
    <parent link="xarm_gripper_base_link"/>
    <child link="right_outer_knuckle"/>
    <axis xyz="-1 0 0"/>
    <limit effort="50" lower="0" upper="0.85" velocity="2"/>
    <mimic joint="drive_joint" multiplier="1" offset="0"/>
  </joint>
  <link name="right_finger">
    <inertial>
      <origin rpy="0 0 0" xyz="2.5618E-14 0.016413 0.029258"/>
      <mass value="0.048304"/>
      <inertia ixx="1.7493E-05" ixy="5.0014E-19" ixz="7.5079E-18" iyy="1.7225E-05" iyz="4.6435E-06" izz="5.1466E-06"/>
    </inertial>
    <visual>
      <geometry>
        <mesh filename="package://xarm_description/meshes/gripper/xarm/right_finger.dae"/>
      </geometry>
      <origin rpy="0 0 0" xyz="0 0 0"/>
    </visual>
    <collision>
      <geometry>
        <mesh filename="package://xarm_description/meshes/gripper/xarm/right_finger.stl"/>
      </geometry>
      <origin rpy="0 0 0" xyz="0 0 0"/>
    </collision>
  </link>
  <joint name="right_finger_joint" type="revolute">
    <origin rpy="0 0 0" xyz="0 -0.035465 0.042039"/>
    <parent link="right_outer_knuckle"/>
    <child link="right_finger"/>
    <axis xyz="1 0 0"/>
    <limit effort="50" lower="0" upper="0.85" velocity="2"/>
    <mimic joint="drive_joint" multiplier="1" offset="0"/>
  </joint>
  <link name="right_inner_knuckle">
    <inertial>
      <origin rpy="0 0 0" xyz="1.866E-06 -0.022047 0.026133"/>
      <mass value="0.023013"/>
      <inertia ixx="6.0949E-06" ixy="6.0665E-11" ixz="-7.191E-11" iyy="6.0197E-06" iyz="-2.7531E-06" izz="5.0784E-06"/>
    </inertial>
    <visual>
      <geometry>
        <mesh filename="package://xarm_description/meshes/gripper/xarm/right_inner_knuckle.dae"/>
      </geometry>
      <origin rpy="0 0 0" xyz="0 0 0"/>
    </visual>
    <collision>
      <geometry>
        <mesh filename="package://xarm_description/meshes/gripper/xarm/right_inner_knuckle.stl"/>
      </geometry>
      <origin rpy="0 0 0" xyz="0 0 0"/>
    </collision>
  </link>
  <joint name="right_inner_knuckle_joint" type="revolute">
    <origin rpy="0 0 0" xyz="0 -0.02 0.074098"/>
    <parent link="xarm_gripper_base_link"/>
    <child link="right_inner_knuckle"/>
    <axis xyz="-1 0 0"/>
    <limit effort="50" lower="0" upper="0.85" velocity="2"/>
    <mimic joint="drive_joint" multiplier="1" offset="0"/>
  </joint>
  <link name="link_tcp"/>
  <joint name="joint_tcp" type="fixed">
    <origin rpy="0 0 0" xyz="0 0 0.172"/>
    <parent link="xarm_gripper_base_link"/>
    <child link="link_tcp"/>
  </joint>
  <transmission name="drive_joint_trans">
    <type>transmission_interface/SimpleTransmission</type>
    <joint name="drive_joint">
      <hardwareInterface>hardware_interface/PositionJointInterface</hardwareInterface>
    </joint>
    <actuator name="drive_joint_motor">
      <hardwareInterface>hardware_interface/PositionJointInterface</hardwareInterface>
      <mechanicalReduction>1</mechanicalReduction>
    </actuator>
  </transmission>
  <gazebo reference="xarm_gripper_base_link">
    <selfCollide>false</selfCollide>
  </gazebo>
  <gazebo reference="left_outer_knuckle">
    <selfCollide>false</selfCollide>
  </gazebo>
  <gazebo reference="left_finger">
    <selfCollide>false</selfCollide>
  </gazebo>
  <gazebo reference="left_inner_knuckle">
    <selfCollide>false</selfCollide>
  </gazebo>
  <gazebo reference="right_outer_knuckle">
    <selfCollide>false</selfCollide>
  </gazebo>
  <gazebo reference="right_finger">
    <selfCollide>false</selfCollide>
  </gazebo>
  <gazebo reference="right_inner_knuckle">
    <selfCollide>false</selfCollide>
  </gazebo>
  <gazebo>
    <plugin filename="libgazebo_mimic_joint_plugin.so" name="left_finger_jointmimic_joint_plugin">
      <joint>drive_joint</joint>
      <mimicJoint>left_finger_joint</mimicJoint>
      <!-- if set to true, PID parameters from "/gazebo_ros_control/pid_gains/${mimic_joint}" are loaded -->
      <hasPID/>
      <multiplier>1.0</multiplier>
      <offset>0</offset>
      <sensitiveness>0.0</sensitiveness>
      <!-- if absolute difference between setpoint and process value is below this threshold, do nothing; 0.0 = disable [rad] -->
      <maxEffort>10.0</maxEffort>
    </plugin>
  </gazebo>
  <gazebo>
    <plugin filename="libgazebo_mimic_joint_plugin.so" name="left_inner_knuckle_jointmimic_joint_plugin">
      <joint>drive_joint</joint>
      <mimicJoint>left_inner_knuckle_joint</mimicJoint>
      <!-- if set to true, PID parameters from "/gazebo_ros_control/pid_gains/${mimic_joint}" are loaded -->
      <hasPID/>
      <multiplier>1.0</multiplier>
      <offset>0</offset>
      <sensitiveness>0.0</sensitiveness>
      <!-- if absolute difference between setpoint and process value is below this threshold, do nothing; 0.0 = disable [rad] -->
      <maxEffort>10.0</maxEffort>
    </plugin>
  </gazebo>
  <gazebo>
    <plugin filename="libgazebo_mimic_joint_plugin.so" name="right_outer_knuckle_jointmimic_joint_plugin">
      <joint>drive_joint</joint>
      <mimicJoint>right_outer_knuckle_joint</mimicJoint>
      <!-- if set to true, PID parameters from "/gazebo_ros_control/pid_gains/${mimic_joint}" are loaded -->
      <hasPID/>
      <multiplier>1.0</multiplier>
      <offset>0</offset>
      <sensitiveness>0.0</sensitiveness>
      <!-- if absolute difference between setpoint and process value is below this threshold, do nothing; 0.0 = disable [rad] -->
      <maxEffort>10.0</maxEffort>
    </plugin>
  </gazebo>
  <gazebo>
    <plugin filename="libgazebo_mimic_joint_plugin.so" name="right_finger_jointmimic_joint_plugin">
      <joint>drive_joint</joint>
      <mimicJoint>right_finger_joint</mimicJoint>
      <!-- if set to true, PID parameters from "/gazebo_ros_control/pid_gains/${mimic_joint}" are loaded -->
      <hasPID/>
      <multiplier>1.0</multiplier>
      <offset>0</offset>
      <sensitiveness>0.0</sensitiveness>
      <!-- if absolute difference between setpoint and process value is below this threshold, do nothing; 0.0 = disable [rad] -->
      <maxEffort>10.0</maxEffort>
    </plugin>
  </gazebo>
  <gazebo>
    <plugin filename="libgazebo_mimic_joint_plugin.so" name="right_inner_knuckle_jointmimic_joint_plugin">
      <joint>drive_joint</joint>
      <mimicJoint>right_inner_knuckle_joint</mimicJoint>
      <!-- if set to true, PID parameters from "/gazebo_ros_control/pid_gains/${mimic_joint}" are loaded -->
      <hasPID/>
      <multiplier>1.0</multiplier>
      <offset>0</offset>
      <sensitiveness>0.0</sensitiveness>
      <!-- if absolute difference between setpoint and process value is below this threshold, do nothing; 0.0 = disable [rad] -->
      <maxEffort>10.0</maxEffort>
    </plugin>
  </gazebo>
  <gazebo>
    <plugin filename="libgazebo_ros2_control.so" name="gazebo_ros2_control">
      <robot_sim_type>gazebo_ros2_control/GazeboSystem</robot_sim_type>
      <parameters>/home/jason/dev_ws/install/xarm_controller/share/xarm_controller/config/xarm6_controllers.yaml</parameters>
    </plugin>
  </gazebo>
  <!-- Insert at the end of xarm_device_macro.xacro -->
</robot>
